[2021-11-15 18:53:27,319] {taskinstance.py:1035} INFO - Dependencies all met for <TaskInstance: covid_ingestion.ingest_BE_to_dwh manual__2021-11-15T18:53:02.173050+00:00 [queued]>
[2021-11-15 18:53:27,337] {taskinstance.py:1035} INFO - Dependencies all met for <TaskInstance: covid_ingestion.ingest_BE_to_dwh manual__2021-11-15T18:53:02.173050+00:00 [queued]>
[2021-11-15 18:53:27,337] {taskinstance.py:1241} INFO - 
--------------------------------------------------------------------------------
[2021-11-15 18:53:27,337] {taskinstance.py:1242} INFO - Starting attempt 1 of 1
[2021-11-15 18:53:27,338] {taskinstance.py:1243} INFO - 
--------------------------------------------------------------------------------
[2021-11-15 18:53:27,375] {taskinstance.py:1262} INFO - Executing <Task(PostgresOperator): ingest_BE_to_dwh> on 2021-11-15 18:53:02.173050+00:00
[2021-11-15 18:53:27,379] {standard_task_runner.py:52} INFO - Started process 4104 to run task
[2021-11-15 18:53:27,383] {standard_task_runner.py:76} INFO - Running: ['***', 'tasks', 'run', 'covid_ingestion', 'ingest_BE_to_dwh', 'manual__2021-11-15T18:53:02.173050+00:00', '--job-id', '200', '--raw', '--subdir', 'DAGS_FOLDER/covid_ingestion.py', '--cfg-path', '/tmp/tmp01idzct9', '--error-file', '/tmp/tmpi8uyyh14']
[2021-11-15 18:53:27,384] {standard_task_runner.py:77} INFO - Job 200: Subtask ingest_BE_to_dwh
[2021-11-15 18:53:27,425] {logging_mixin.py:109} INFO - Running <TaskInstance: covid_ingestion.ingest_BE_to_dwh manual__2021-11-15T18:53:02.173050+00:00 [running]> on host 6f9154c92b39
[2021-11-15 18:53:27,465] {taskinstance.py:1703} ERROR - Task failed with exception
Traceback (most recent call last):
  File "/home/airflow/.local/lib/python3.7/site-packages/airflow/models/taskinstance.py", line 1332, in _run_raw_task
    self._execute_task_with_callbacks(context)
  File "/home/airflow/.local/lib/python3.7/site-packages/airflow/models/taskinstance.py", line 1421, in _execute_task_with_callbacks
    self.render_templates(context=context)
  File "/home/airflow/.local/lib/python3.7/site-packages/airflow/models/taskinstance.py", line 2113, in render_templates
    self.task.render_template_fields(context)
  File "/home/airflow/.local/lib/python3.7/site-packages/airflow/models/baseoperator.py", line 1057, in render_template_fields
    self._do_render_template_fields(self, self.template_fields, context, jinja_env, set())
  File "/home/airflow/.local/lib/python3.7/site-packages/airflow/models/baseoperator.py", line 1070, in _do_render_template_fields
    rendered_content = self.render_template(content, context, jinja_env, seen_oids)
  File "/home/airflow/.local/lib/python3.7/site-packages/airflow/models/baseoperator.py", line 1107, in render_template
    return jinja_env.from_string(content).render(**context)
  File "/home/airflow/.local/lib/python3.7/site-packages/jinja2/environment.py", line 1090, in render
    self.environment.handle_exception()
  File "/home/airflow/.local/lib/python3.7/site-packages/jinja2/environment.py", line 832, in handle_exception
    reraise(*rewrite_traceback_stack(source=source))
  File "/home/airflow/.local/lib/python3.7/site-packages/jinja2/_compat.py", line 28, in reraise
    raise value.with_traceback(tb)
  File "<template>", line 3, in top-level template code
jinja2.exceptions.UndefinedError: 'str object' has no attribute 'positive'
[2021-11-15 18:53:27,478] {taskinstance.py:1280} INFO - Marking task as FAILED. dag_id=covid_ingestion, task_id=ingest_BE_to_dwh, execution_date=20211115T185302, start_date=20211115T185327, end_date=20211115T185327
[2021-11-15 18:53:27,491] {standard_task_runner.py:91} ERROR - Failed to execute job 200 for task ingest_BE_to_dwh
Traceback (most recent call last):
  File "/home/airflow/.local/lib/python3.7/site-packages/airflow/task/task_runner/standard_task_runner.py", line 85, in _start_by_fork
    args.func(args, dag=self.dag)
  File "/home/airflow/.local/lib/python3.7/site-packages/airflow/cli/cli_parser.py", line 48, in command
    return func(*args, **kwargs)
  File "/home/airflow/.local/lib/python3.7/site-packages/airflow/utils/cli.py", line 92, in wrapper
    return f(*args, **kwargs)
  File "/home/airflow/.local/lib/python3.7/site-packages/airflow/cli/commands/task_command.py", line 292, in task_run
    _run_task_by_selected_method(args, dag, ti)
  File "/home/airflow/.local/lib/python3.7/site-packages/airflow/cli/commands/task_command.py", line 107, in _run_task_by_selected_method
    _run_raw_task(args, ti)
  File "/home/airflow/.local/lib/python3.7/site-packages/airflow/cli/commands/task_command.py", line 184, in _run_raw_task
    error_file=args.error_file,
  File "/home/airflow/.local/lib/python3.7/site-packages/airflow/utils/session.py", line 70, in wrapper
    return func(*args, session=session, **kwargs)
  File "/home/airflow/.local/lib/python3.7/site-packages/airflow/models/taskinstance.py", line 1332, in _run_raw_task
    self._execute_task_with_callbacks(context)
  File "/home/airflow/.local/lib/python3.7/site-packages/airflow/models/taskinstance.py", line 1421, in _execute_task_with_callbacks
    self.render_templates(context=context)
  File "/home/airflow/.local/lib/python3.7/site-packages/airflow/models/taskinstance.py", line 2113, in render_templates
    self.task.render_template_fields(context)
  File "/home/airflow/.local/lib/python3.7/site-packages/airflow/models/baseoperator.py", line 1057, in render_template_fields
    self._do_render_template_fields(self, self.template_fields, context, jinja_env, set())
  File "/home/airflow/.local/lib/python3.7/site-packages/airflow/models/baseoperator.py", line 1070, in _do_render_template_fields
    rendered_content = self.render_template(content, context, jinja_env, seen_oids)
  File "/home/airflow/.local/lib/python3.7/site-packages/airflow/models/baseoperator.py", line 1107, in render_template
    return jinja_env.from_string(content).render(**context)
  File "/home/airflow/.local/lib/python3.7/site-packages/jinja2/environment.py", line 1090, in render
    self.environment.handle_exception()
  File "/home/airflow/.local/lib/python3.7/site-packages/jinja2/environment.py", line 832, in handle_exception
    reraise(*rewrite_traceback_stack(source=source))
  File "/home/airflow/.local/lib/python3.7/site-packages/jinja2/_compat.py", line 28, in reraise
    raise value.with_traceback(tb)
  File "<template>", line 3, in top-level template code
jinja2.exceptions.UndefinedError: 'str object' has no attribute 'positive'
[2021-11-15 18:53:27,514] {local_task_job.py:154} INFO - Task exited with return code 1
[2021-11-15 18:53:27,546] {local_task_job.py:264} INFO - 0 downstream tasks scheduled from follow-on schedule check
