[2021-11-15 08:14:56,770] {taskinstance.py:1035} INFO - Dependencies all met for <TaskInstance: init_dwh_conn.build-tables scheduled__2021-11-08T00:00:00+00:00 [queued]>
[2021-11-15 08:14:56,783] {taskinstance.py:1035} INFO - Dependencies all met for <TaskInstance: init_dwh_conn.build-tables scheduled__2021-11-08T00:00:00+00:00 [queued]>
[2021-11-15 08:14:56,783] {taskinstance.py:1241} INFO - 
--------------------------------------------------------------------------------
[2021-11-15 08:14:56,783] {taskinstance.py:1242} INFO - Starting attempt 1 of 1
[2021-11-15 08:14:56,783] {taskinstance.py:1243} INFO - 
--------------------------------------------------------------------------------
[2021-11-15 08:14:56,800] {taskinstance.py:1262} INFO - Executing <Task(PostgresOperator): build-tables> on 2021-11-08 00:00:00+00:00
[2021-11-15 08:14:56,803] {standard_task_runner.py:52} INFO - Started process 92 to run task
[2021-11-15 08:14:56,806] {standard_task_runner.py:76} INFO - Running: ['***', 'tasks', 'run', 'init_dwh_conn', 'build-tables', 'scheduled__2021-11-08T00:00:00+00:00', '--job-id', '4', '--raw', '--subdir', 'DAGS_FOLDER/initialize_dwh.py', '--cfg-path', '/tmp/tmp9j1f09o9', '--error-file', '/tmp/tmpo8e7qwo7']
[2021-11-15 08:14:56,807] {standard_task_runner.py:77} INFO - Job 4: Subtask build-tables
[2021-11-15 08:14:56,842] {logging_mixin.py:109} INFO - Running <TaskInstance: init_dwh_conn.build-tables scheduled__2021-11-08T00:00:00+00:00 [running]> on host 887b886e8ba1
[2021-11-15 08:14:56,892] {taskinstance.py:1429} INFO - Exporting the following env vars:
AIRFLOW_CTX_DAG_OWNER=***
AIRFLOW_CTX_DAG_ID=init_dwh_conn
AIRFLOW_CTX_TASK_ID=build-tables
AIRFLOW_CTX_EXECUTION_DATE=2021-11-08T00:00:00+00:00
AIRFLOW_CTX_DAG_RUN_ID=scheduled__2021-11-08T00:00:00+00:00
[2021-11-15 08:14:56,900] {base.py:79} INFO - Using connection to: id: postgres_dwh. Host: postgres, Port: 3084, Schema: None, Login: ***, Password: ***, extra: {}
[2021-11-15 08:14:56,901] {taskinstance.py:1703} ERROR - Task failed with exception
Traceback (most recent call last):
  File "/home/airflow/.local/lib/python3.7/site-packages/airflow/models/taskinstance.py", line 1332, in _run_raw_task
    self._execute_task_with_callbacks(context)
  File "/home/airflow/.local/lib/python3.7/site-packages/airflow/models/taskinstance.py", line 1458, in _execute_task_with_callbacks
    result = self._execute_task(context, self.task)
  File "/home/airflow/.local/lib/python3.7/site-packages/airflow/models/taskinstance.py", line 1514, in _execute_task
    result = execute_callable(context=context)
  File "/home/airflow/.local/lib/python3.7/site-packages/airflow/providers/postgres/operators/postgres.py", line 69, in execute
    self.hook.run(self.sql, self.autocommit, parameters=self.parameters)
  File "/home/airflow/.local/lib/python3.7/site-packages/airflow/hooks/dbapi.py", line 198, in run
    with closing(self.get_conn()) as conn:
  File "/home/airflow/.local/lib/python3.7/site-packages/airflow/providers/postgres/hooks/postgres.py", line 115, in get_conn
    self.conn = psycopg2.connect(**conn_args)
  File "/home/airflow/.local/lib/python3.7/site-packages/psycopg2/__init__.py", line 122, in connect
    conn = _connect(dsn, connection_factory=connection_factory, **kwasync)
psycopg2.OperationalError: could not connect to server: Connection refused
	Is the server running on host "postgres" (192.168.160.2) and accepting
	TCP/IP connections on port 3084?

[2021-11-15 08:14:56,913] {taskinstance.py:1280} INFO - Marking task as FAILED. dag_id=init_dwh_conn, task_id=build-tables, execution_date=20211108T000000, start_date=20211115T081456, end_date=20211115T081456
[2021-11-15 08:14:56,927] {standard_task_runner.py:91} ERROR - Failed to execute job 4 for task build-tables
Traceback (most recent call last):
  File "/home/airflow/.local/lib/python3.7/site-packages/airflow/task/task_runner/standard_task_runner.py", line 85, in _start_by_fork
    args.func(args, dag=self.dag)
  File "/home/airflow/.local/lib/python3.7/site-packages/airflow/cli/cli_parser.py", line 48, in command
    return func(*args, **kwargs)
  File "/home/airflow/.local/lib/python3.7/site-packages/airflow/utils/cli.py", line 92, in wrapper
    return f(*args, **kwargs)
  File "/home/airflow/.local/lib/python3.7/site-packages/airflow/cli/commands/task_command.py", line 292, in task_run
    _run_task_by_selected_method(args, dag, ti)
  File "/home/airflow/.local/lib/python3.7/site-packages/airflow/cli/commands/task_command.py", line 107, in _run_task_by_selected_method
    _run_raw_task(args, ti)
  File "/home/airflow/.local/lib/python3.7/site-packages/airflow/cli/commands/task_command.py", line 184, in _run_raw_task
    error_file=args.error_file,
  File "/home/airflow/.local/lib/python3.7/site-packages/airflow/utils/session.py", line 70, in wrapper
    return func(*args, session=session, **kwargs)
  File "/home/airflow/.local/lib/python3.7/site-packages/airflow/models/taskinstance.py", line 1332, in _run_raw_task
    self._execute_task_with_callbacks(context)
  File "/home/airflow/.local/lib/python3.7/site-packages/airflow/models/taskinstance.py", line 1458, in _execute_task_with_callbacks
    result = self._execute_task(context, self.task)
  File "/home/airflow/.local/lib/python3.7/site-packages/airflow/models/taskinstance.py", line 1514, in _execute_task
    result = execute_callable(context=context)
  File "/home/airflow/.local/lib/python3.7/site-packages/airflow/providers/postgres/operators/postgres.py", line 69, in execute
    self.hook.run(self.sql, self.autocommit, parameters=self.parameters)
  File "/home/airflow/.local/lib/python3.7/site-packages/airflow/hooks/dbapi.py", line 198, in run
    with closing(self.get_conn()) as conn:
  File "/home/airflow/.local/lib/python3.7/site-packages/airflow/providers/postgres/hooks/postgres.py", line 115, in get_conn
    self.conn = psycopg2.connect(**conn_args)
  File "/home/airflow/.local/lib/python3.7/site-packages/psycopg2/__init__.py", line 122, in connect
    conn = _connect(dsn, connection_factory=connection_factory, **kwasync)
psycopg2.OperationalError: could not connect to server: Connection refused
	Is the server running on host "postgres" (192.168.160.2) and accepting
	TCP/IP connections on port 3084?

[2021-11-15 08:14:56,938] {local_task_job.py:154} INFO - Task exited with return code 1
[2021-11-15 08:14:56,969] {local_task_job.py:264} INFO - 0 downstream tasks scheduled from follow-on schedule check
[2021-11-15 08:21:01,574] {taskinstance.py:1035} INFO - Dependencies all met for <TaskInstance: init_dwh_conn.build-tables scheduled__2021-11-08T00:00:00+00:00 [queued]>
[2021-11-15 08:21:01,590] {taskinstance.py:1035} INFO - Dependencies all met for <TaskInstance: init_dwh_conn.build-tables scheduled__2021-11-08T00:00:00+00:00 [queued]>
[2021-11-15 08:21:01,590] {taskinstance.py:1241} INFO - 
--------------------------------------------------------------------------------
[2021-11-15 08:21:01,590] {taskinstance.py:1242} INFO - Starting attempt 1 of 1
[2021-11-15 08:21:01,591] {taskinstance.py:1243} INFO - 
--------------------------------------------------------------------------------
[2021-11-15 08:21:01,609] {taskinstance.py:1262} INFO - Executing <Task(PostgresOperator): build-tables> on 2021-11-08 00:00:00+00:00
[2021-11-15 08:21:01,613] {standard_task_runner.py:52} INFO - Started process 90 to run task
[2021-11-15 08:21:01,617] {standard_task_runner.py:76} INFO - Running: ['***', 'tasks', 'run', 'init_dwh_conn', 'build-tables', 'scheduled__2021-11-08T00:00:00+00:00', '--job-id', '4', '--raw', '--subdir', 'DAGS_FOLDER/initialize_dwh.py', '--cfg-path', '/tmp/tmpb9n1pg15', '--error-file', '/tmp/tmpd2_zuidw']
[2021-11-15 08:21:01,618] {standard_task_runner.py:77} INFO - Job 4: Subtask build-tables
[2021-11-15 08:21:01,658] {logging_mixin.py:109} INFO - Running <TaskInstance: init_dwh_conn.build-tables scheduled__2021-11-08T00:00:00+00:00 [running]> on host 8b2742eb2ad3
[2021-11-15 08:21:01,710] {taskinstance.py:1429} INFO - Exporting the following env vars:
AIRFLOW_CTX_DAG_OWNER=***
AIRFLOW_CTX_DAG_ID=init_dwh_conn
AIRFLOW_CTX_TASK_ID=build-tables
AIRFLOW_CTX_EXECUTION_DATE=2021-11-08T00:00:00+00:00
AIRFLOW_CTX_DAG_RUN_ID=scheduled__2021-11-08T00:00:00+00:00
[2021-11-15 08:21:01,719] {base.py:79} INFO - Using connection to: id: postgres_dwh. Host: postgres-dwh, Port: 3084, Schema: None, Login: ***, Password: ***, extra: {}
[2021-11-15 08:21:01,721] {taskinstance.py:1703} ERROR - Task failed with exception
Traceback (most recent call last):
  File "/home/airflow/.local/lib/python3.7/site-packages/airflow/models/taskinstance.py", line 1332, in _run_raw_task
    self._execute_task_with_callbacks(context)
  File "/home/airflow/.local/lib/python3.7/site-packages/airflow/models/taskinstance.py", line 1458, in _execute_task_with_callbacks
    result = self._execute_task(context, self.task)
  File "/home/airflow/.local/lib/python3.7/site-packages/airflow/models/taskinstance.py", line 1514, in _execute_task
    result = execute_callable(context=context)
  File "/home/airflow/.local/lib/python3.7/site-packages/airflow/providers/postgres/operators/postgres.py", line 69, in execute
    self.hook.run(self.sql, self.autocommit, parameters=self.parameters)
  File "/home/airflow/.local/lib/python3.7/site-packages/airflow/hooks/dbapi.py", line 198, in run
    with closing(self.get_conn()) as conn:
  File "/home/airflow/.local/lib/python3.7/site-packages/airflow/providers/postgres/hooks/postgres.py", line 115, in get_conn
    self.conn = psycopg2.connect(**conn_args)
  File "/home/airflow/.local/lib/python3.7/site-packages/psycopg2/__init__.py", line 122, in connect
    conn = _connect(dsn, connection_factory=connection_factory, **kwasync)
psycopg2.OperationalError: could not connect to server: Connection refused
	Is the server running on host "postgres-dwh" (192.168.176.5) and accepting
	TCP/IP connections on port 3084?

[2021-11-15 08:21:01,734] {taskinstance.py:1280} INFO - Marking task as FAILED. dag_id=init_dwh_conn, task_id=build-tables, execution_date=20211108T000000, start_date=20211115T082101, end_date=20211115T082101
[2021-11-15 08:21:01,748] {standard_task_runner.py:91} ERROR - Failed to execute job 4 for task build-tables
Traceback (most recent call last):
  File "/home/airflow/.local/lib/python3.7/site-packages/airflow/task/task_runner/standard_task_runner.py", line 85, in _start_by_fork
    args.func(args, dag=self.dag)
  File "/home/airflow/.local/lib/python3.7/site-packages/airflow/cli/cli_parser.py", line 48, in command
    return func(*args, **kwargs)
  File "/home/airflow/.local/lib/python3.7/site-packages/airflow/utils/cli.py", line 92, in wrapper
    return f(*args, **kwargs)
  File "/home/airflow/.local/lib/python3.7/site-packages/airflow/cli/commands/task_command.py", line 292, in task_run
    _run_task_by_selected_method(args, dag, ti)
  File "/home/airflow/.local/lib/python3.7/site-packages/airflow/cli/commands/task_command.py", line 107, in _run_task_by_selected_method
    _run_raw_task(args, ti)
  File "/home/airflow/.local/lib/python3.7/site-packages/airflow/cli/commands/task_command.py", line 184, in _run_raw_task
    error_file=args.error_file,
  File "/home/airflow/.local/lib/python3.7/site-packages/airflow/utils/session.py", line 70, in wrapper
    return func(*args, session=session, **kwargs)
  File "/home/airflow/.local/lib/python3.7/site-packages/airflow/models/taskinstance.py", line 1332, in _run_raw_task
    self._execute_task_with_callbacks(context)
  File "/home/airflow/.local/lib/python3.7/site-packages/airflow/models/taskinstance.py", line 1458, in _execute_task_with_callbacks
    result = self._execute_task(context, self.task)
  File "/home/airflow/.local/lib/python3.7/site-packages/airflow/models/taskinstance.py", line 1514, in _execute_task
    result = execute_callable(context=context)
  File "/home/airflow/.local/lib/python3.7/site-packages/airflow/providers/postgres/operators/postgres.py", line 69, in execute
    self.hook.run(self.sql, self.autocommit, parameters=self.parameters)
  File "/home/airflow/.local/lib/python3.7/site-packages/airflow/hooks/dbapi.py", line 198, in run
    with closing(self.get_conn()) as conn:
  File "/home/airflow/.local/lib/python3.7/site-packages/airflow/providers/postgres/hooks/postgres.py", line 115, in get_conn
    self.conn = psycopg2.connect(**conn_args)
  File "/home/airflow/.local/lib/python3.7/site-packages/psycopg2/__init__.py", line 122, in connect
    conn = _connect(dsn, connection_factory=connection_factory, **kwasync)
psycopg2.OperationalError: could not connect to server: Connection refused
	Is the server running on host "postgres-dwh" (192.168.176.5) and accepting
	TCP/IP connections on port 3084?

[2021-11-15 08:21:01,789] {local_task_job.py:154} INFO - Task exited with return code 1
[2021-11-15 08:21:01,819] {local_task_job.py:264} INFO - 0 downstream tasks scheduled from follow-on schedule check
[2021-11-15 08:26:06,466] {taskinstance.py:1035} INFO - Dependencies all met for <TaskInstance: init_dwh_conn.build-tables scheduled__2021-11-08T00:00:00+00:00 [queued]>
[2021-11-15 08:26:06,486] {taskinstance.py:1035} INFO - Dependencies all met for <TaskInstance: init_dwh_conn.build-tables scheduled__2021-11-08T00:00:00+00:00 [queued]>
[2021-11-15 08:26:06,486] {taskinstance.py:1241} INFO - 
--------------------------------------------------------------------------------
[2021-11-15 08:26:06,487] {taskinstance.py:1242} INFO - Starting attempt 1 of 1
[2021-11-15 08:26:06,487] {taskinstance.py:1243} INFO - 
--------------------------------------------------------------------------------
[2021-11-15 08:26:06,500] {taskinstance.py:1262} INFO - Executing <Task(PostgresOperator): build-tables> on 2021-11-08 00:00:00+00:00
[2021-11-15 08:26:06,504] {standard_task_runner.py:52} INFO - Started process 83 to run task
[2021-11-15 08:26:06,506] {standard_task_runner.py:76} INFO - Running: ['***', 'tasks', 'run', 'init_dwh_conn', 'build-tables', 'scheduled__2021-11-08T00:00:00+00:00', '--job-id', '4', '--raw', '--subdir', 'DAGS_FOLDER/initialize_dwh.py', '--cfg-path', '/tmp/tmpcj8ci1gc', '--error-file', '/tmp/tmpjb0kojzu']
[2021-11-15 08:26:06,507] {standard_task_runner.py:77} INFO - Job 4: Subtask build-tables
[2021-11-15 08:26:06,541] {logging_mixin.py:109} INFO - Running <TaskInstance: init_dwh_conn.build-tables scheduled__2021-11-08T00:00:00+00:00 [running]> on host 74a5c3d08dc7
[2021-11-15 08:26:06,586] {taskinstance.py:1429} INFO - Exporting the following env vars:
AIRFLOW_CTX_DAG_OWNER=***
AIRFLOW_CTX_DAG_ID=init_dwh_conn
AIRFLOW_CTX_TASK_ID=build-tables
AIRFLOW_CTX_EXECUTION_DATE=2021-11-08T00:00:00+00:00
AIRFLOW_CTX_DAG_RUN_ID=scheduled__2021-11-08T00:00:00+00:00
[2021-11-15 08:26:06,595] {base.py:79} INFO - Using connection to: id: postgres_dwh. Host: postgres-dwh, Port: 3084, Schema: None, Login: ***, Password: ***, extra: {}
[2021-11-15 08:26:06,596] {taskinstance.py:1703} ERROR - Task failed with exception
Traceback (most recent call last):
  File "/home/airflow/.local/lib/python3.7/site-packages/airflow/models/taskinstance.py", line 1332, in _run_raw_task
    self._execute_task_with_callbacks(context)
  File "/home/airflow/.local/lib/python3.7/site-packages/airflow/models/taskinstance.py", line 1458, in _execute_task_with_callbacks
    result = self._execute_task(context, self.task)
  File "/home/airflow/.local/lib/python3.7/site-packages/airflow/models/taskinstance.py", line 1514, in _execute_task
    result = execute_callable(context=context)
  File "/home/airflow/.local/lib/python3.7/site-packages/airflow/providers/postgres/operators/postgres.py", line 69, in execute
    self.hook.run(self.sql, self.autocommit, parameters=self.parameters)
  File "/home/airflow/.local/lib/python3.7/site-packages/airflow/hooks/dbapi.py", line 198, in run
    with closing(self.get_conn()) as conn:
  File "/home/airflow/.local/lib/python3.7/site-packages/airflow/providers/postgres/hooks/postgres.py", line 115, in get_conn
    self.conn = psycopg2.connect(**conn_args)
  File "/home/airflow/.local/lib/python3.7/site-packages/psycopg2/__init__.py", line 122, in connect
    conn = _connect(dsn, connection_factory=connection_factory, **kwasync)
psycopg2.OperationalError: could not connect to server: Connection refused
	Is the server running on host "postgres-dwh" (192.168.192.5) and accepting
	TCP/IP connections on port 3084?

[2021-11-15 08:26:06,611] {taskinstance.py:1280} INFO - Marking task as FAILED. dag_id=init_dwh_conn, task_id=build-tables, execution_date=20211108T000000, start_date=20211115T082606, end_date=20211115T082606
[2021-11-15 08:26:06,628] {standard_task_runner.py:91} ERROR - Failed to execute job 4 for task build-tables
Traceback (most recent call last):
  File "/home/airflow/.local/lib/python3.7/site-packages/airflow/task/task_runner/standard_task_runner.py", line 85, in _start_by_fork
    args.func(args, dag=self.dag)
  File "/home/airflow/.local/lib/python3.7/site-packages/airflow/cli/cli_parser.py", line 48, in command
    return func(*args, **kwargs)
  File "/home/airflow/.local/lib/python3.7/site-packages/airflow/utils/cli.py", line 92, in wrapper
    return f(*args, **kwargs)
  File "/home/airflow/.local/lib/python3.7/site-packages/airflow/cli/commands/task_command.py", line 292, in task_run
    _run_task_by_selected_method(args, dag, ti)
  File "/home/airflow/.local/lib/python3.7/site-packages/airflow/cli/commands/task_command.py", line 107, in _run_task_by_selected_method
    _run_raw_task(args, ti)
  File "/home/airflow/.local/lib/python3.7/site-packages/airflow/cli/commands/task_command.py", line 184, in _run_raw_task
    error_file=args.error_file,
  File "/home/airflow/.local/lib/python3.7/site-packages/airflow/utils/session.py", line 70, in wrapper
    return func(*args, session=session, **kwargs)
  File "/home/airflow/.local/lib/python3.7/site-packages/airflow/models/taskinstance.py", line 1332, in _run_raw_task
    self._execute_task_with_callbacks(context)
  File "/home/airflow/.local/lib/python3.7/site-packages/airflow/models/taskinstance.py", line 1458, in _execute_task_with_callbacks
    result = self._execute_task(context, self.task)
  File "/home/airflow/.local/lib/python3.7/site-packages/airflow/models/taskinstance.py", line 1514, in _execute_task
    result = execute_callable(context=context)
  File "/home/airflow/.local/lib/python3.7/site-packages/airflow/providers/postgres/operators/postgres.py", line 69, in execute
    self.hook.run(self.sql, self.autocommit, parameters=self.parameters)
  File "/home/airflow/.local/lib/python3.7/site-packages/airflow/hooks/dbapi.py", line 198, in run
    with closing(self.get_conn()) as conn:
  File "/home/airflow/.local/lib/python3.7/site-packages/airflow/providers/postgres/hooks/postgres.py", line 115, in get_conn
    self.conn = psycopg2.connect(**conn_args)
  File "/home/airflow/.local/lib/python3.7/site-packages/psycopg2/__init__.py", line 122, in connect
    conn = _connect(dsn, connection_factory=connection_factory, **kwasync)
psycopg2.OperationalError: could not connect to server: Connection refused
	Is the server running on host "postgres-dwh" (192.168.192.5) and accepting
	TCP/IP connections on port 3084?

[2021-11-15 08:26:06,638] {local_task_job.py:154} INFO - Task exited with return code 1
[2021-11-15 08:26:06,668] {local_task_job.py:264} INFO - 0 downstream tasks scheduled from follow-on schedule check
[2021-11-15 08:41:56,231] {taskinstance.py:1035} INFO - Dependencies all met for <TaskInstance: init_dwh_conn.build-tables scheduled__2021-11-08T00:00:00+00:00 [queued]>
[2021-11-15 08:41:56,244] {taskinstance.py:1035} INFO - Dependencies all met for <TaskInstance: init_dwh_conn.build-tables scheduled__2021-11-08T00:00:00+00:00 [queued]>
[2021-11-15 08:41:56,244] {taskinstance.py:1241} INFO - 
--------------------------------------------------------------------------------
[2021-11-15 08:41:56,245] {taskinstance.py:1242} INFO - Starting attempt 1 of 1
[2021-11-15 08:41:56,245] {taskinstance.py:1243} INFO - 
--------------------------------------------------------------------------------
[2021-11-15 08:41:56,281] {taskinstance.py:1262} INFO - Executing <Task(PostgresOperator): build-tables> on 2021-11-08 00:00:00+00:00
[2021-11-15 08:41:56,288] {standard_task_runner.py:52} INFO - Started process 73 to run task
[2021-11-15 08:41:56,293] {standard_task_runner.py:76} INFO - Running: ['***', 'tasks', 'run', 'init_dwh_conn', 'build-tables', 'scheduled__2021-11-08T00:00:00+00:00', '--job-id', '4', '--raw', '--subdir', 'DAGS_FOLDER/initialize_dwh.py', '--cfg-path', '/tmp/tmpssf3wwfu', '--error-file', '/tmp/tmphnoliwqx']
[2021-11-15 08:41:56,293] {standard_task_runner.py:77} INFO - Job 4: Subtask build-tables
[2021-11-15 08:41:56,349] {logging_mixin.py:109} INFO - Running <TaskInstance: init_dwh_conn.build-tables scheduled__2021-11-08T00:00:00+00:00 [running]> on host 6f9154c92b39
[2021-11-15 08:41:56,401] {taskinstance.py:1429} INFO - Exporting the following env vars:
AIRFLOW_CTX_DAG_OWNER=***
AIRFLOW_CTX_DAG_ID=init_dwh_conn
AIRFLOW_CTX_TASK_ID=build-tables
AIRFLOW_CTX_EXECUTION_DATE=2021-11-08T00:00:00+00:00
AIRFLOW_CTX_DAG_RUN_ID=scheduled__2021-11-08T00:00:00+00:00
[2021-11-15 08:41:56,410] {base.py:79} INFO - Using connection to: id: postgres_dwh. Host: postgres-dwh, Port: 5432, Schema: None, Login: ***, Password: ***, extra: {}
[2021-11-15 08:41:56,413] {dbapi.py:225} INFO - Running statement: DROP TABLE IF EXISTS fact_covid;
DROP TABLE IF EXISTS dim_test;
DROP TABLE IF EXISTS dim_deaths;
DROP TABLE IF EXISTS dim_municipality;
DROP TABLE IF EXISTS dim_canton;
DROP TABLE IF EXISTS dim_infections;
DROP TABLE IF EXISTS dim_date;

CREATE TABLE dim_test (
  test_key    SERIAL PRIMARY KEY,
  positive    INTEGER,
  negative    INTEGER,
  total       INTEGER,
  positivity_rate INTEGER,
  week_number     INTEGER,
  source          TEXT

);

CREATE TABLE dim_deaths (
  deaths_key SERIAL PRIMARY KEY,
  amount INTEGER,
  canton INTEGER
);

CREATE TABLE dim_municipality(
  postal_code_key INTEGER PRIMARY KEY,
  place VARCHAR(50)
);

CREATE TABLE dim_canton(
  canton_key SERIAL PRIMARY KEY,
  place VARCHAR(50)
);

CREATE TABLE dim_infections (
  infection_key SERIAL PRIMARY KEY,
  confirmed INTEGER,
  postal_code INTEGER,
  canton INTEGER
);

CREATE TABLE dim_date (
  date_key SERIAL PRIMARY KEY,
  day INTEGER,
  month INTEGER,
  year INTEGER,
  hour INTEGER,
  minute INTEGER,
  second INTEGER
);

CREATE TABLE fact_covid (
    covid_key     SERIAL PRIMARY KEY,
    dim_test      INTEGER,
    dim_deaths    INTEGER,
    dim_municipality  INTEGER,
    dim_canton    INTEGER,
    dim_infections INTEGER,
    dim_date      INTEGER,
    created_date TIMESTAMP NOT NULL DEFAULT current_timestamp,

    CONSTRAINT fk_test
      FOREIGN KEY(dim_test)
	  REFERENCES dim_test(test_key),

    CONSTRAINT fk_deaths
      FOREIGN KEY(dim_deaths)
    REFERENCES dim_deaths(deaths_key),

    CONSTRAINT fk_municipality
      FOREIGN KEY(dim_municipality)
	  REFERENCES dim_municipality(postal_code_key),

    CONSTRAINT fk_canton
      FOREIGN KEY(dim_canton)
	  REFERENCES dim_canton(canton_key),

    CONSTRAINT fk_infections
      FOREIGN KEY(dim_infections)
	  REFERENCES dim_infections(infection_key),

    CONSTRAINT fk_date
      FOREIGN KEY(dim_date)
    REFERENCES dim_date(date_key)

);, parameters: None
[2021-11-15 08:41:56,449] {postgres.py:71} INFO - NOTICE:  table "fact_covid" does not exist, skipping

[2021-11-15 08:41:56,449] {postgres.py:71} INFO - NOTICE:  table "dim_test" does not exist, skipping

[2021-11-15 08:41:56,449] {postgres.py:71} INFO - NOTICE:  table "dim_deaths" does not exist, skipping

[2021-11-15 08:41:56,449] {postgres.py:71} INFO - NOTICE:  table "dim_municipality" does not exist, skipping

[2021-11-15 08:41:56,449] {postgres.py:71} INFO - NOTICE:  table "dim_canton" does not exist, skipping

[2021-11-15 08:41:56,449] {postgres.py:71} INFO - NOTICE:  table "dim_infections" does not exist, skipping

[2021-11-15 08:41:56,449] {postgres.py:71} INFO - NOTICE:  table "dim_date" does not exist, skipping

[2021-11-15 08:41:56,460] {taskinstance.py:1280} INFO - Marking task as SUCCESS. dag_id=init_dwh_conn, task_id=build-tables, execution_date=20211108T000000, start_date=20211115T084156, end_date=20211115T084156
[2021-11-15 08:41:56,505] {local_task_job.py:154} INFO - Task exited with return code 0
[2021-11-15 08:41:56,539] {local_task_job.py:264} INFO - 0 downstream tasks scheduled from follow-on schedule check
