[2021-11-15 09:52:59,807] {taskinstance.py:1035} INFO - Dependencies all met for <TaskInstance: covid_ingestion.process_BE manual__2021-11-15T09:52:56.491392+00:00 [queued]>
[2021-11-15 09:52:59,820] {taskinstance.py:1035} INFO - Dependencies all met for <TaskInstance: covid_ingestion.process_BE manual__2021-11-15T09:52:56.491392+00:00 [queued]>
[2021-11-15 09:52:59,820] {taskinstance.py:1241} INFO - 
--------------------------------------------------------------------------------
[2021-11-15 09:52:59,820] {taskinstance.py:1242} INFO - Starting attempt 1 of 1
[2021-11-15 09:52:59,820] {taskinstance.py:1243} INFO - 
--------------------------------------------------------------------------------
[2021-11-15 09:52:59,838] {taskinstance.py:1262} INFO - Executing <Task(PythonOperator): process_BE> on 2021-11-15 09:52:56.491392+00:00
[2021-11-15 09:52:59,843] {standard_task_runner.py:52} INFO - Started process 2752 to run task
[2021-11-15 09:52:59,847] {standard_task_runner.py:76} INFO - Running: ['***', 'tasks', 'run', 'covid_ingestion', 'process_BE', 'manual__2021-11-15T09:52:56.491392+00:00', '--job-id', '40', '--raw', '--subdir', 'DAGS_FOLDER/covid_ingestion.py', '--cfg-path', '/tmp/tmpf7cuqgik', '--error-file', '/tmp/tmp30x5_9yi']
[2021-11-15 09:52:59,848] {standard_task_runner.py:77} INFO - Job 40: Subtask process_BE
[2021-11-15 09:52:59,892] {logging_mixin.py:109} INFO - Running <TaskInstance: covid_ingestion.process_BE manual__2021-11-15T09:52:56.491392+00:00 [running]> on host 6f9154c92b39
[2021-11-15 09:52:59,942] {taskinstance.py:1429} INFO - Exporting the following env vars:
AIRFLOW_CTX_DAG_OWNER=***
AIRFLOW_CTX_DAG_ID=covid_ingestion
AIRFLOW_CTX_TASK_ID=process_BE
AIRFLOW_CTX_EXECUTION_DATE=2021-11-15T09:52:56.491392+00:00
AIRFLOW_CTX_DAG_RUN_ID=manual__2021-11-15T09:52:56.491392+00:00
[2021-11-15 09:52:59,950] {taskinstance.py:1703} ERROR - Task failed with exception
Traceback (most recent call last):
  File "/home/airflow/.local/lib/python3.7/site-packages/airflow/models/taskinstance.py", line 1332, in _run_raw_task
    self._execute_task_with_callbacks(context)
  File "/home/airflow/.local/lib/python3.7/site-packages/airflow/models/taskinstance.py", line 1458, in _execute_task_with_callbacks
    result = self._execute_task(context, self.task)
  File "/home/airflow/.local/lib/python3.7/site-packages/airflow/models/taskinstance.py", line 1514, in _execute_task
    result = execute_callable(context=context)
  File "/home/airflow/.local/lib/python3.7/site-packages/airflow/operators/python.py", line 151, in execute
    return_value = self.execute_callable()
  File "/home/airflow/.local/lib/python3.7/site-packages/airflow/operators/python.py", line 162, in execute_callable
    return self.python_callable(*self.op_args, **self.op_kwargs)
  File "/opt/airflow/dags/covid_ingestion.py", line 64, in process_BE
    data = {{ ti.xcom_pull(task_ids='process_BE',key='return_value') }}
TypeError: unhashable type: 'set'
[2021-11-15 09:52:59,965] {taskinstance.py:1280} INFO - Marking task as FAILED. dag_id=covid_ingestion, task_id=process_BE, execution_date=20211115T095256, start_date=20211115T095259, end_date=20211115T095259
[2021-11-15 09:52:59,982] {standard_task_runner.py:91} ERROR - Failed to execute job 40 for task process_BE
Traceback (most recent call last):
  File "/home/airflow/.local/lib/python3.7/site-packages/airflow/task/task_runner/standard_task_runner.py", line 85, in _start_by_fork
    args.func(args, dag=self.dag)
  File "/home/airflow/.local/lib/python3.7/site-packages/airflow/cli/cli_parser.py", line 48, in command
    return func(*args, **kwargs)
  File "/home/airflow/.local/lib/python3.7/site-packages/airflow/utils/cli.py", line 92, in wrapper
    return f(*args, **kwargs)
  File "/home/airflow/.local/lib/python3.7/site-packages/airflow/cli/commands/task_command.py", line 292, in task_run
    _run_task_by_selected_method(args, dag, ti)
  File "/home/airflow/.local/lib/python3.7/site-packages/airflow/cli/commands/task_command.py", line 107, in _run_task_by_selected_method
    _run_raw_task(args, ti)
  File "/home/airflow/.local/lib/python3.7/site-packages/airflow/cli/commands/task_command.py", line 184, in _run_raw_task
    error_file=args.error_file,
  File "/home/airflow/.local/lib/python3.7/site-packages/airflow/utils/session.py", line 70, in wrapper
    return func(*args, session=session, **kwargs)
  File "/home/airflow/.local/lib/python3.7/site-packages/airflow/models/taskinstance.py", line 1332, in _run_raw_task
    self._execute_task_with_callbacks(context)
  File "/home/airflow/.local/lib/python3.7/site-packages/airflow/models/taskinstance.py", line 1458, in _execute_task_with_callbacks
    result = self._execute_task(context, self.task)
  File "/home/airflow/.local/lib/python3.7/site-packages/airflow/models/taskinstance.py", line 1514, in _execute_task
    result = execute_callable(context=context)
  File "/home/airflow/.local/lib/python3.7/site-packages/airflow/operators/python.py", line 151, in execute
    return_value = self.execute_callable()
  File "/home/airflow/.local/lib/python3.7/site-packages/airflow/operators/python.py", line 162, in execute_callable
    return self.python_callable(*self.op_args, **self.op_kwargs)
  File "/opt/airflow/dags/covid_ingestion.py", line 64, in process_BE
    data = {{ ti.xcom_pull(task_ids='process_BE',key='return_value') }}
TypeError: unhashable type: 'set'
[2021-11-15 09:53:00,018] {local_task_job.py:154} INFO - Task exited with return code 1
[2021-11-15 09:53:00,055] {local_task_job.py:264} INFO - 0 downstream tasks scheduled from follow-on schedule check
