[2021-11-15 20:33:59,399] {taskinstance.py:1035} INFO - Dependencies all met for <TaskInstance: init_dwh_conn.initialize_dwh_conn manual__2021-11-15T20:33:58.491952+00:00 [queued]>
[2021-11-15 20:33:59,413] {taskinstance.py:1035} INFO - Dependencies all met for <TaskInstance: init_dwh_conn.initialize_dwh_conn manual__2021-11-15T20:33:58.491952+00:00 [queued]>
[2021-11-15 20:33:59,413] {taskinstance.py:1241} INFO - 
--------------------------------------------------------------------------------
[2021-11-15 20:33:59,414] {taskinstance.py:1242} INFO - Starting attempt 1 of 1
[2021-11-15 20:33:59,414] {taskinstance.py:1243} INFO - 
--------------------------------------------------------------------------------
[2021-11-15 20:33:59,431] {taskinstance.py:1262} INFO - Executing <Task(PythonOperator): initialize_dwh_conn> on 2021-11-15 20:33:58.491952+00:00
[2021-11-15 20:33:59,435] {standard_task_runner.py:52} INFO - Started process 2080 to run task
[2021-11-15 20:33:59,438] {standard_task_runner.py:76} INFO - Running: ['***', 'tasks', 'run', 'init_dwh_conn', 'initialize_dwh_conn', 'manual__2021-11-15T20:33:58.491952+00:00', '--job-id', '84', '--raw', '--subdir', 'DAGS_FOLDER/initialize_dwh.py', '--cfg-path', '/tmp/tmpiqz3okgg', '--error-file', '/tmp/tmp798qr6vt']
[2021-11-15 20:33:59,438] {standard_task_runner.py:77} INFO - Job 84: Subtask initialize_dwh_conn
[2021-11-15 20:33:59,475] {logging_mixin.py:109} INFO - Running <TaskInstance: init_dwh_conn.initialize_dwh_conn manual__2021-11-15T20:33:58.491952+00:00 [running]> on host e693d79b64a2
[2021-11-15 20:33:59,520] {taskinstance.py:1429} INFO - Exporting the following env vars:
AIRFLOW_CTX_DAG_OWNER=***
AIRFLOW_CTX_DAG_ID=init_dwh_conn
AIRFLOW_CTX_TASK_ID=initialize_dwh_conn
AIRFLOW_CTX_EXECUTION_DATE=2021-11-15T20:33:58.491952+00:00
AIRFLOW_CTX_DAG_RUN_ID=manual__2021-11-15T20:33:58.491952+00:00
[2021-11-15 20:33:59,521] {initialize_dwh.py:33} INFO - Creating connections and definining sql path
[2021-11-15 20:33:59,521] {crypto.py:82} WARNING - empty cryptography key - values will not be stored encrypted.
[2021-11-15 20:33:59,527] {taskinstance.py:1703} ERROR - Task failed with exception
Traceback (most recent call last):
  File "/home/airflow/.local/lib/python3.7/site-packages/sqlalchemy/engine/base.py", line 1277, in _execute_context
    cursor, statement, parameters, context
  File "/home/airflow/.local/lib/python3.7/site-packages/sqlalchemy/engine/default.py", line 608, in do_execute
    cursor.execute(statement, parameters)
psycopg2.errors.UniqueViolation: duplicate key value violates unique constraint "unique_conn_id"
DETAIL:  Key (conn_id)=(postgres_dwh) already exists.


The above exception was the direct cause of the following exception:

Traceback (most recent call last):
  File "/home/airflow/.local/lib/python3.7/site-packages/airflow/models/taskinstance.py", line 1332, in _run_raw_task
    self._execute_task_with_callbacks(context)
  File "/home/airflow/.local/lib/python3.7/site-packages/airflow/models/taskinstance.py", line 1458, in _execute_task_with_callbacks
    result = self._execute_task(context, self.task)
  File "/home/airflow/.local/lib/python3.7/site-packages/airflow/models/taskinstance.py", line 1514, in _execute_task
    result = execute_callable(context=context)
  File "/home/airflow/.local/lib/python3.7/site-packages/airflow/operators/python.py", line 151, in execute
    return_value = self.execute_callable()
  File "/home/airflow/.local/lib/python3.7/site-packages/airflow/operators/python.py", line 162, in execute_callable
    return self.python_callable(*self.op_args, **self.op_kwargs)
  File "/opt/airflow/dags/initialize_dwh.py", line 49, in initialize_dwh_conn
    create_new_conn(session)
  File "/opt/airflow/dags/initialize_dwh.py", line 47, in create_new_conn
    session.commit()
  File "/home/airflow/.local/lib/python3.7/site-packages/sqlalchemy/orm/session.py", line 1046, in commit
    self.transaction.commit()
  File "/home/airflow/.local/lib/python3.7/site-packages/sqlalchemy/orm/session.py", line 504, in commit
    self._prepare_impl()
  File "/home/airflow/.local/lib/python3.7/site-packages/sqlalchemy/orm/session.py", line 483, in _prepare_impl
    self.session.flush()
  File "/home/airflow/.local/lib/python3.7/site-packages/sqlalchemy/orm/session.py", line 2540, in flush
    self._flush(objects)
  File "/home/airflow/.local/lib/python3.7/site-packages/sqlalchemy/orm/session.py", line 2682, in _flush
    transaction.rollback(_capture_exception=True)
  File "/home/airflow/.local/lib/python3.7/site-packages/sqlalchemy/util/langhelpers.py", line 70, in __exit__
    with_traceback=exc_tb,
  File "/home/airflow/.local/lib/python3.7/site-packages/sqlalchemy/util/compat.py", line 182, in raise_
    raise exception
  File "/home/airflow/.local/lib/python3.7/site-packages/sqlalchemy/orm/session.py", line 2642, in _flush
    flush_context.execute()
  File "/home/airflow/.local/lib/python3.7/site-packages/sqlalchemy/orm/unitofwork.py", line 422, in execute
    rec.execute(self)
  File "/home/airflow/.local/lib/python3.7/site-packages/sqlalchemy/orm/unitofwork.py", line 589, in execute
    uow,
  File "/home/airflow/.local/lib/python3.7/site-packages/sqlalchemy/orm/persistence.py", line 245, in save_obj
    insert,
  File "/home/airflow/.local/lib/python3.7/site-packages/sqlalchemy/orm/persistence.py", line 1136, in _emit_insert_statements
    statement, params
  File "/home/airflow/.local/lib/python3.7/site-packages/sqlalchemy/engine/base.py", line 1011, in execute
    return meth(self, multiparams, params)
  File "/home/airflow/.local/lib/python3.7/site-packages/sqlalchemy/sql/elements.py", line 298, in _execute_on_connection
    return connection._execute_clauseelement(self, multiparams, params)
  File "/home/airflow/.local/lib/python3.7/site-packages/sqlalchemy/engine/base.py", line 1130, in _execute_clauseelement
    distilled_params,
  File "/home/airflow/.local/lib/python3.7/site-packages/sqlalchemy/engine/base.py", line 1317, in _execute_context
    e, statement, parameters, cursor, context
  File "/home/airflow/.local/lib/python3.7/site-packages/sqlalchemy/engine/base.py", line 1511, in _handle_dbapi_exception
    sqlalchemy_exception, with_traceback=exc_info[2], from_=e
  File "/home/airflow/.local/lib/python3.7/site-packages/sqlalchemy/util/compat.py", line 182, in raise_
    raise exception
  File "/home/airflow/.local/lib/python3.7/site-packages/sqlalchemy/engine/base.py", line 1277, in _execute_context
    cursor, statement, parameters, context
  File "/home/airflow/.local/lib/python3.7/site-packages/sqlalchemy/engine/default.py", line 608, in do_execute
    cursor.execute(statement, parameters)
sqlalchemy.exc.IntegrityError: (psycopg2.errors.UniqueViolation) duplicate key value violates unique constraint "unique_conn_id"
DETAIL:  Key (conn_id)=(postgres_dwh) already exists.

[SQL: INSERT INTO connection (conn_id, conn_type, description, host, schema, login, password, port, is_encrypted, is_extra_encrypted, extra) VALUES (%(conn_id)s, %(conn_type)s, %(description)s, %(host)s, %(schema)s, %(login)s, %(password)s, %(port)s, %(is_encrypted)s, %(is_extra_encrypted)s, %(extra)s) RETURNING connection.id]
[parameters: {'conn_id': 'postgres_dwh', 'conn_type': 'postgres', 'description': None, 'host': 'postgres-dwh', 'schema': None, 'login': 'airflow', 'password': 'airflow', 'port': '5432', 'is_encrypted': False, 'is_extra_encrypted': False, 'extra': None}]
(Background on this error at: http://sqlalche.me/e/13/gkpj)
[2021-11-15 20:33:59,547] {taskinstance.py:1280} INFO - Marking task as FAILED. dag_id=init_dwh_conn, task_id=initialize_dwh_conn, execution_date=20211115T203358, start_date=20211115T203359, end_date=20211115T203359
[2021-11-15 20:33:59,559] {standard_task_runner.py:91} ERROR - Failed to execute job 84 for task initialize_dwh_conn
Traceback (most recent call last):
  File "/home/airflow/.local/lib/python3.7/site-packages/sqlalchemy/engine/base.py", line 1277, in _execute_context
    cursor, statement, parameters, context
  File "/home/airflow/.local/lib/python3.7/site-packages/sqlalchemy/engine/default.py", line 608, in do_execute
    cursor.execute(statement, parameters)
psycopg2.errors.UniqueViolation: duplicate key value violates unique constraint "unique_conn_id"
DETAIL:  Key (conn_id)=(postgres_dwh) already exists.


The above exception was the direct cause of the following exception:

Traceback (most recent call last):
  File "/home/airflow/.local/lib/python3.7/site-packages/airflow/task/task_runner/standard_task_runner.py", line 85, in _start_by_fork
    args.func(args, dag=self.dag)
  File "/home/airflow/.local/lib/python3.7/site-packages/airflow/cli/cli_parser.py", line 48, in command
    return func(*args, **kwargs)
  File "/home/airflow/.local/lib/python3.7/site-packages/airflow/utils/cli.py", line 92, in wrapper
    return f(*args, **kwargs)
  File "/home/airflow/.local/lib/python3.7/site-packages/airflow/cli/commands/task_command.py", line 292, in task_run
    _run_task_by_selected_method(args, dag, ti)
  File "/home/airflow/.local/lib/python3.7/site-packages/airflow/cli/commands/task_command.py", line 107, in _run_task_by_selected_method
    _run_raw_task(args, ti)
  File "/home/airflow/.local/lib/python3.7/site-packages/airflow/cli/commands/task_command.py", line 184, in _run_raw_task
    error_file=args.error_file,
  File "/home/airflow/.local/lib/python3.7/site-packages/airflow/utils/session.py", line 70, in wrapper
    return func(*args, session=session, **kwargs)
  File "/home/airflow/.local/lib/python3.7/site-packages/airflow/models/taskinstance.py", line 1332, in _run_raw_task
    self._execute_task_with_callbacks(context)
  File "/home/airflow/.local/lib/python3.7/site-packages/airflow/models/taskinstance.py", line 1458, in _execute_task_with_callbacks
    result = self._execute_task(context, self.task)
  File "/home/airflow/.local/lib/python3.7/site-packages/airflow/models/taskinstance.py", line 1514, in _execute_task
    result = execute_callable(context=context)
  File "/home/airflow/.local/lib/python3.7/site-packages/airflow/operators/python.py", line 151, in execute
    return_value = self.execute_callable()
  File "/home/airflow/.local/lib/python3.7/site-packages/airflow/operators/python.py", line 162, in execute_callable
    return self.python_callable(*self.op_args, **self.op_kwargs)
  File "/opt/airflow/dags/initialize_dwh.py", line 49, in initialize_dwh_conn
    create_new_conn(session)
  File "/opt/airflow/dags/initialize_dwh.py", line 47, in create_new_conn
    session.commit()
  File "/home/airflow/.local/lib/python3.7/site-packages/sqlalchemy/orm/session.py", line 1046, in commit
    self.transaction.commit()
  File "/home/airflow/.local/lib/python3.7/site-packages/sqlalchemy/orm/session.py", line 504, in commit
    self._prepare_impl()
  File "/home/airflow/.local/lib/python3.7/site-packages/sqlalchemy/orm/session.py", line 483, in _prepare_impl
    self.session.flush()
  File "/home/airflow/.local/lib/python3.7/site-packages/sqlalchemy/orm/session.py", line 2540, in flush
    self._flush(objects)
  File "/home/airflow/.local/lib/python3.7/site-packages/sqlalchemy/orm/session.py", line 2682, in _flush
    transaction.rollback(_capture_exception=True)
  File "/home/airflow/.local/lib/python3.7/site-packages/sqlalchemy/util/langhelpers.py", line 70, in __exit__
    with_traceback=exc_tb,
  File "/home/airflow/.local/lib/python3.7/site-packages/sqlalchemy/util/compat.py", line 182, in raise_
    raise exception
  File "/home/airflow/.local/lib/python3.7/site-packages/sqlalchemy/orm/session.py", line 2642, in _flush
    flush_context.execute()
  File "/home/airflow/.local/lib/python3.7/site-packages/sqlalchemy/orm/unitofwork.py", line 422, in execute
    rec.execute(self)
  File "/home/airflow/.local/lib/python3.7/site-packages/sqlalchemy/orm/unitofwork.py", line 589, in execute
    uow,
  File "/home/airflow/.local/lib/python3.7/site-packages/sqlalchemy/orm/persistence.py", line 245, in save_obj
    insert,
  File "/home/airflow/.local/lib/python3.7/site-packages/sqlalchemy/orm/persistence.py", line 1136, in _emit_insert_statements
    statement, params
  File "/home/airflow/.local/lib/python3.7/site-packages/sqlalchemy/engine/base.py", line 1011, in execute
    return meth(self, multiparams, params)
  File "/home/airflow/.local/lib/python3.7/site-packages/sqlalchemy/sql/elements.py", line 298, in _execute_on_connection
    return connection._execute_clauseelement(self, multiparams, params)
  File "/home/airflow/.local/lib/python3.7/site-packages/sqlalchemy/engine/base.py", line 1130, in _execute_clauseelement
    distilled_params,
  File "/home/airflow/.local/lib/python3.7/site-packages/sqlalchemy/engine/base.py", line 1317, in _execute_context
    e, statement, parameters, cursor, context
  File "/home/airflow/.local/lib/python3.7/site-packages/sqlalchemy/engine/base.py", line 1511, in _handle_dbapi_exception
    sqlalchemy_exception, with_traceback=exc_info[2], from_=e
  File "/home/airflow/.local/lib/python3.7/site-packages/sqlalchemy/util/compat.py", line 182, in raise_
    raise exception
  File "/home/airflow/.local/lib/python3.7/site-packages/sqlalchemy/engine/base.py", line 1277, in _execute_context
    cursor, statement, parameters, context
  File "/home/airflow/.local/lib/python3.7/site-packages/sqlalchemy/engine/default.py", line 608, in do_execute
    cursor.execute(statement, parameters)
sqlalchemy.exc.IntegrityError: (psycopg2.errors.UniqueViolation) duplicate key value violates unique constraint "unique_conn_id"
DETAIL:  Key (conn_id)=(postgres_dwh) already exists.

[SQL: INSERT INTO connection (conn_id, conn_type, description, host, schema, login, password, port, is_encrypted, is_extra_encrypted, extra) VALUES (%(conn_id)s, %(conn_type)s, %(description)s, %(host)s, %(schema)s, %(login)s, %(password)s, %(port)s, %(is_encrypted)s, %(is_extra_encrypted)s, %(extra)s) RETURNING connection.id]
[parameters: {'conn_id': 'postgres_dwh', 'conn_type': 'postgres', 'description': None, 'host': 'postgres-dwh', 'schema': None, 'login': 'airflow', 'password': 'airflow', 'port': '5432', 'is_encrypted': False, 'is_extra_encrypted': False, 'extra': None}]
(Background on this error at: http://sqlalche.me/e/13/gkpj)
[2021-11-15 20:33:59,609] {local_task_job.py:154} INFO - Task exited with return code 1
[2021-11-15 20:33:59,651] {local_task_job.py:264} INFO - 0 downstream tasks scheduled from follow-on schedule check
