[2021-11-15 10:43:56,720] {taskinstance.py:1035} INFO - Dependencies all met for <TaskInstance: covid_ingestion.process_BE manual__2021-11-15T10:43:53.501525+00:00 [queued]>
[2021-11-15 10:43:56,732] {taskinstance.py:1035} INFO - Dependencies all met for <TaskInstance: covid_ingestion.process_BE manual__2021-11-15T10:43:53.501525+00:00 [queued]>
[2021-11-15 10:43:56,733] {taskinstance.py:1241} INFO - 
--------------------------------------------------------------------------------
[2021-11-15 10:43:56,733] {taskinstance.py:1242} INFO - Starting attempt 1 of 1
[2021-11-15 10:43:56,733] {taskinstance.py:1243} INFO - 
--------------------------------------------------------------------------------
[2021-11-15 10:43:56,751] {taskinstance.py:1262} INFO - Executing <Task(PythonOperator): process_BE> on 2021-11-15 10:43:53.501525+00:00
[2021-11-15 10:43:56,755] {standard_task_runner.py:52} INFO - Started process 4770 to run task
[2021-11-15 10:43:56,759] {standard_task_runner.py:76} INFO - Running: ['***', 'tasks', 'run', 'covid_ingestion', 'process_BE', 'manual__2021-11-15T10:43:53.501525+00:00', '--job-id', '100', '--raw', '--subdir', 'DAGS_FOLDER/covid_ingestion.py', '--cfg-path', '/tmp/tmpb_85k591', '--error-file', '/tmp/tmpekrdf6ef']
[2021-11-15 10:43:56,760] {standard_task_runner.py:77} INFO - Job 100: Subtask process_BE
[2021-11-15 10:43:56,797] {logging_mixin.py:109} INFO - Running <TaskInstance: covid_ingestion.process_BE manual__2021-11-15T10:43:53.501525+00:00 [running]> on host 6f9154c92b39
[2021-11-15 10:43:56,841] {taskinstance.py:1429} INFO - Exporting the following env vars:
AIRFLOW_CTX_DAG_OWNER=***
AIRFLOW_CTX_DAG_ID=covid_ingestion
AIRFLOW_CTX_TASK_ID=process_BE
AIRFLOW_CTX_EXECUTION_DATE=2021-11-15T10:43:53.501525+00:00
AIRFLOW_CTX_DAG_RUN_ID=manual__2021-11-15T10:43:53.501525+00:00
[2021-11-15 10:43:56,856] {taskinstance.py:1703} ERROR - Task failed with exception
Traceback (most recent call last):
  File "/home/airflow/.local/lib/python3.7/site-packages/airflow/models/taskinstance.py", line 1332, in _run_raw_task
    self._execute_task_with_callbacks(context)
  File "/home/airflow/.local/lib/python3.7/site-packages/airflow/models/taskinstance.py", line 1458, in _execute_task_with_callbacks
    result = self._execute_task(context, self.task)
  File "/home/airflow/.local/lib/python3.7/site-packages/airflow/models/taskinstance.py", line 1514, in _execute_task
    result = execute_callable(context=context)
  File "/home/airflow/.local/lib/python3.7/site-packages/airflow/operators/python.py", line 151, in execute
    return_value = self.execute_callable()
  File "/home/airflow/.local/lib/python3.7/site-packages/airflow/operators/python.py", line 162, in execute_callable
    return self.python_callable(*self.op_args, **self.op_kwargs)
  File "/opt/airflow/dags/covid_ingestion.py", line 74, in process_BE
    csv_tests = pd.read_csv(str_cases, header=0)
  File "/home/airflow/.local/lib/python3.7/site-packages/pandas/util/_decorators.py", line 311, in wrapper
    return func(*args, **kwargs)
  File "/home/airflow/.local/lib/python3.7/site-packages/pandas/io/parsers/readers.py", line 586, in read_csv
    return _read(filepath_or_buffer, kwds)
  File "/home/airflow/.local/lib/python3.7/site-packages/pandas/io/parsers/readers.py", line 482, in _read
    parser = TextFileReader(filepath_or_buffer, **kwds)
  File "/home/airflow/.local/lib/python3.7/site-packages/pandas/io/parsers/readers.py", line 811, in __init__
    self._engine = self._make_engine(self.engine)
  File "/home/airflow/.local/lib/python3.7/site-packages/pandas/io/parsers/readers.py", line 1040, in _make_engine
    return mapping[engine](self.f, **self.options)  # type: ignore[call-arg]
  File "/home/airflow/.local/lib/python3.7/site-packages/pandas/io/parsers/c_parser_wrapper.py", line 69, in __init__
    self._reader = parsers.TextReader(self.handles.handle, **kwds)
  File "pandas/_libs/parsers.pyx", line 549, in pandas._libs.parsers.TextReader.__cinit__
pandas.errors.EmptyDataError: No columns to parse from file
[2021-11-15 10:43:56,868] {taskinstance.py:1280} INFO - Marking task as FAILED. dag_id=covid_ingestion, task_id=process_BE, execution_date=20211115T104353, start_date=20211115T104356, end_date=20211115T104356
[2021-11-15 10:43:56,881] {standard_task_runner.py:91} ERROR - Failed to execute job 100 for task process_BE
Traceback (most recent call last):
  File "/home/airflow/.local/lib/python3.7/site-packages/airflow/task/task_runner/standard_task_runner.py", line 85, in _start_by_fork
    args.func(args, dag=self.dag)
  File "/home/airflow/.local/lib/python3.7/site-packages/airflow/cli/cli_parser.py", line 48, in command
    return func(*args, **kwargs)
  File "/home/airflow/.local/lib/python3.7/site-packages/airflow/utils/cli.py", line 92, in wrapper
    return f(*args, **kwargs)
  File "/home/airflow/.local/lib/python3.7/site-packages/airflow/cli/commands/task_command.py", line 292, in task_run
    _run_task_by_selected_method(args, dag, ti)
  File "/home/airflow/.local/lib/python3.7/site-packages/airflow/cli/commands/task_command.py", line 107, in _run_task_by_selected_method
    _run_raw_task(args, ti)
  File "/home/airflow/.local/lib/python3.7/site-packages/airflow/cli/commands/task_command.py", line 184, in _run_raw_task
    error_file=args.error_file,
  File "/home/airflow/.local/lib/python3.7/site-packages/airflow/utils/session.py", line 70, in wrapper
    return func(*args, session=session, **kwargs)
  File "/home/airflow/.local/lib/python3.7/site-packages/airflow/models/taskinstance.py", line 1332, in _run_raw_task
    self._execute_task_with_callbacks(context)
  File "/home/airflow/.local/lib/python3.7/site-packages/airflow/models/taskinstance.py", line 1458, in _execute_task_with_callbacks
    result = self._execute_task(context, self.task)
  File "/home/airflow/.local/lib/python3.7/site-packages/airflow/models/taskinstance.py", line 1514, in _execute_task
    result = execute_callable(context=context)
  File "/home/airflow/.local/lib/python3.7/site-packages/airflow/operators/python.py", line 151, in execute
    return_value = self.execute_callable()
  File "/home/airflow/.local/lib/python3.7/site-packages/airflow/operators/python.py", line 162, in execute_callable
    return self.python_callable(*self.op_args, **self.op_kwargs)
  File "/opt/airflow/dags/covid_ingestion.py", line 74, in process_BE
    csv_tests = pd.read_csv(str_cases, header=0)
  File "/home/airflow/.local/lib/python3.7/site-packages/pandas/util/_decorators.py", line 311, in wrapper
    return func(*args, **kwargs)
  File "/home/airflow/.local/lib/python3.7/site-packages/pandas/io/parsers/readers.py", line 586, in read_csv
    return _read(filepath_or_buffer, kwds)
  File "/home/airflow/.local/lib/python3.7/site-packages/pandas/io/parsers/readers.py", line 482, in _read
    parser = TextFileReader(filepath_or_buffer, **kwds)
  File "/home/airflow/.local/lib/python3.7/site-packages/pandas/io/parsers/readers.py", line 811, in __init__
    self._engine = self._make_engine(self.engine)
  File "/home/airflow/.local/lib/python3.7/site-packages/pandas/io/parsers/readers.py", line 1040, in _make_engine
    return mapping[engine](self.f, **self.options)  # type: ignore[call-arg]
  File "/home/airflow/.local/lib/python3.7/site-packages/pandas/io/parsers/c_parser_wrapper.py", line 69, in __init__
    self._reader = parsers.TextReader(self.handles.handle, **kwds)
  File "pandas/_libs/parsers.pyx", line 549, in pandas._libs.parsers.TextReader.__cinit__
pandas.errors.EmptyDataError: No columns to parse from file
[2021-11-15 10:43:56,890] {local_task_job.py:154} INFO - Task exited with return code 1
[2021-11-15 10:43:56,918] {local_task_job.py:264} INFO - 0 downstream tasks scheduled from follow-on schedule check
