[2021-11-15 10:22:22,443] {taskinstance.py:1035} INFO - Dependencies all met for <TaskInstance: covid_ingestion.process_BE manual__2021-11-15T10:22:19.777718+00:00 [queued]>
[2021-11-15 10:22:22,455] {taskinstance.py:1035} INFO - Dependencies all met for <TaskInstance: covid_ingestion.process_BE manual__2021-11-15T10:22:19.777718+00:00 [queued]>
[2021-11-15 10:22:22,455] {taskinstance.py:1241} INFO - 
--------------------------------------------------------------------------------
[2021-11-15 10:22:22,456] {taskinstance.py:1242} INFO - Starting attempt 1 of 1
[2021-11-15 10:22:22,456] {taskinstance.py:1243} INFO - 
--------------------------------------------------------------------------------
[2021-11-15 10:22:22,473] {taskinstance.py:1262} INFO - Executing <Task(PythonOperator): process_BE> on 2021-11-15 10:22:19.777718+00:00
[2021-11-15 10:22:22,477] {standard_task_runner.py:52} INFO - Started process 3906 to run task
[2021-11-15 10:22:22,480] {standard_task_runner.py:76} INFO - Running: ['***', 'tasks', 'run', 'covid_ingestion', 'process_BE', 'manual__2021-11-15T10:22:19.777718+00:00', '--job-id', '70', '--raw', '--subdir', 'DAGS_FOLDER/covid_ingestion.py', '--cfg-path', '/tmp/tmp88phih0r', '--error-file', '/tmp/tmpli75h4um']
[2021-11-15 10:22:22,481] {standard_task_runner.py:77} INFO - Job 70: Subtask process_BE
[2021-11-15 10:22:22,517] {logging_mixin.py:109} INFO - Running <TaskInstance: covid_ingestion.process_BE manual__2021-11-15T10:22:19.777718+00:00 [running]> on host 6f9154c92b39
[2021-11-15 10:22:22,565] {taskinstance.py:1429} INFO - Exporting the following env vars:
AIRFLOW_CTX_DAG_OWNER=***
AIRFLOW_CTX_DAG_ID=covid_ingestion
AIRFLOW_CTX_TASK_ID=process_BE
AIRFLOW_CTX_EXECUTION_DATE=2021-11-15T10:22:19.777718+00:00
AIRFLOW_CTX_DAG_RUN_ID=manual__2021-11-15T10:22:19.777718+00:00
[2021-11-15 10:22:22,572] {logging_mixin.py:109} INFO - [None]
[2021-11-15 10:22:22,573] {logging_mixin.py:109} INFO - [None]
[2021-11-15 10:22:22,573] {logging_mixin.py:109} INFO - [None]
[2021-11-15 10:22:22,573] {logging_mixin.py:109} INFO - [None]
[2021-11-15 10:22:22,573] {logging_mixin.py:109} INFO - [None]
[2021-11-15 10:22:22,573] {logging_mixin.py:109} INFO - [None]
[2021-11-15 10:22:22,573] {logging_mixin.py:109} INFO - [None]
[2021-11-15 10:22:22,573] {logging_mixin.py:109} INFO - [None]
[2021-11-15 10:22:22,573] {logging_mixin.py:109} INFO - [None]
[2021-11-15 10:22:22,573] {logging_mixin.py:109} INFO - [None]
[2021-11-15 10:22:22,573] {taskinstance.py:1703} ERROR - Task failed with exception
Traceback (most recent call last):
  File "/home/airflow/.local/lib/python3.7/site-packages/airflow/models/taskinstance.py", line 1332, in _run_raw_task
    self._execute_task_with_callbacks(context)
  File "/home/airflow/.local/lib/python3.7/site-packages/airflow/models/taskinstance.py", line 1458, in _execute_task_with_callbacks
    result = self._execute_task(context, self.task)
  File "/home/airflow/.local/lib/python3.7/site-packages/airflow/models/taskinstance.py", line 1514, in _execute_task
    result = execute_callable(context=context)
  File "/home/airflow/.local/lib/python3.7/site-packages/airflow/operators/python.py", line 151, in execute
    return_value = self.execute_callable()
  File "/home/airflow/.local/lib/python3.7/site-packages/airflow/operators/python.py", line 162, in execute_callable
    return self.python_callable(*self.op_args, **self.op_kwargs)
  File "/opt/airflow/dags/covid_ingestion.py", line 73, in process_BE
    csv_cases = pd.read_csv(bern_data["cases"])
TypeError: list indices must be integers or slices, not str
[2021-11-15 10:22:22,586] {taskinstance.py:1280} INFO - Marking task as FAILED. dag_id=covid_ingestion, task_id=process_BE, execution_date=20211115T102219, start_date=20211115T102222, end_date=20211115T102222
[2021-11-15 10:22:22,599] {standard_task_runner.py:91} ERROR - Failed to execute job 70 for task process_BE
Traceback (most recent call last):
  File "/home/airflow/.local/lib/python3.7/site-packages/airflow/task/task_runner/standard_task_runner.py", line 85, in _start_by_fork
    args.func(args, dag=self.dag)
  File "/home/airflow/.local/lib/python3.7/site-packages/airflow/cli/cli_parser.py", line 48, in command
    return func(*args, **kwargs)
  File "/home/airflow/.local/lib/python3.7/site-packages/airflow/utils/cli.py", line 92, in wrapper
    return f(*args, **kwargs)
  File "/home/airflow/.local/lib/python3.7/site-packages/airflow/cli/commands/task_command.py", line 292, in task_run
    _run_task_by_selected_method(args, dag, ti)
  File "/home/airflow/.local/lib/python3.7/site-packages/airflow/cli/commands/task_command.py", line 107, in _run_task_by_selected_method
    _run_raw_task(args, ti)
  File "/home/airflow/.local/lib/python3.7/site-packages/airflow/cli/commands/task_command.py", line 184, in _run_raw_task
    error_file=args.error_file,
  File "/home/airflow/.local/lib/python3.7/site-packages/airflow/utils/session.py", line 70, in wrapper
    return func(*args, session=session, **kwargs)
  File "/home/airflow/.local/lib/python3.7/site-packages/airflow/models/taskinstance.py", line 1332, in _run_raw_task
    self._execute_task_with_callbacks(context)
  File "/home/airflow/.local/lib/python3.7/site-packages/airflow/models/taskinstance.py", line 1458, in _execute_task_with_callbacks
    result = self._execute_task(context, self.task)
  File "/home/airflow/.local/lib/python3.7/site-packages/airflow/models/taskinstance.py", line 1514, in _execute_task
    result = execute_callable(context=context)
  File "/home/airflow/.local/lib/python3.7/site-packages/airflow/operators/python.py", line 151, in execute
    return_value = self.execute_callable()
  File "/home/airflow/.local/lib/python3.7/site-packages/airflow/operators/python.py", line 162, in execute_callable
    return self.python_callable(*self.op_args, **self.op_kwargs)
  File "/opt/airflow/dags/covid_ingestion.py", line 73, in process_BE
    csv_cases = pd.read_csv(bern_data["cases"])
TypeError: list indices must be integers or slices, not str
[2021-11-15 10:22:22,612] {local_task_job.py:154} INFO - Task exited with return code 1
[2021-11-15 10:22:22,643] {local_task_job.py:264} INFO - 0 downstream tasks scheduled from follow-on schedule check
