[2021-11-15 08:53:58,990] {taskinstance.py:1035} INFO - Dependencies all met for <TaskInstance: covid_ingestion.ingest_to_dwh scheduled__2021-11-13T00:00:00+00:00 [queued]>
[2021-11-15 08:53:59,007] {taskinstance.py:1035} INFO - Dependencies all met for <TaskInstance: covid_ingestion.ingest_to_dwh scheduled__2021-11-13T00:00:00+00:00 [queued]>
[2021-11-15 08:53:59,008] {taskinstance.py:1241} INFO - 
--------------------------------------------------------------------------------
[2021-11-15 08:53:59,008] {taskinstance.py:1242} INFO - Starting attempt 1 of 1
[2021-11-15 08:53:59,008] {taskinstance.py:1243} INFO - 
--------------------------------------------------------------------------------
[2021-11-15 08:53:59,034] {taskinstance.py:1262} INFO - Executing <Task(PostgresOperator): ingest_to_dwh> on 2021-11-13 00:00:00+00:00
[2021-11-15 08:53:59,039] {standard_task_runner.py:52} INFO - Started process 553 to run task
[2021-11-15 08:53:59,041] {standard_task_runner.py:76} INFO - Running: ['***', 'tasks', 'run', 'covid_ingestion', 'ingest_to_dwh', 'scheduled__2021-11-13T00:00:00+00:00', '--job-id', '18', '--raw', '--subdir', 'DAGS_FOLDER/covid_ingestion.py', '--cfg-path', '/tmp/tmpiou6h93n', '--error-file', '/tmp/tmp7xjrs4r9']
[2021-11-15 08:53:59,042] {standard_task_runner.py:77} INFO - Job 18: Subtask ingest_to_dwh
[2021-11-15 08:53:59,080] {logging_mixin.py:109} INFO - Running <TaskInstance: covid_ingestion.ingest_to_dwh scheduled__2021-11-13T00:00:00+00:00 [running]> on host 6f9154c92b39
[2021-11-15 08:53:59,132] {taskinstance.py:1429} INFO - Exporting the following env vars:
AIRFLOW_CTX_DAG_OWNER=***
AIRFLOW_CTX_DAG_ID=covid_ingestion
AIRFLOW_CTX_TASK_ID=ingest_to_dwh
AIRFLOW_CTX_EXECUTION_DATE=2021-11-13T00:00:00+00:00
AIRFLOW_CTX_DAG_RUN_ID=scheduled__2021-11-13T00:00:00+00:00
[2021-11-15 08:53:59,140] {base.py:79} INFO - Using connection to: id: postgres_dwh. Host: postgres-dwh, Port: 5432, Schema: None, Login: ***, Password: ***, extra: {}
[2021-11-15 08:53:59,143] {dbapi.py:225} INFO - Running statement: 
            CREATE TABLE IF NOT EXISTS pet (
            pet_id SERIAL PRIMARY KEY,
            name VARCHAR NOT NULL,
            pet_type VARCHAR NOT NULL,
            birth_date DATE NOT NULL,
            OWNER VARCHAR NOT NULL);
          , parameters: None
[2021-11-15 08:53:59,144] {postgres.py:71} INFO - NOTICE:  relation "pet" already exists, skipping

[2021-11-15 08:53:59,155] {taskinstance.py:1280} INFO - Marking task as SUCCESS. dag_id=covid_ingestion, task_id=ingest_to_dwh, execution_date=20211113T000000, start_date=20211115T085358, end_date=20211115T085359
[2021-11-15 08:53:59,213] {local_task_job.py:154} INFO - Task exited with return code 0
[2021-11-15 08:53:59,270] {local_task_job.py:264} INFO - 0 downstream tasks scheduled from follow-on schedule check
[2021-11-15 19:47:40,029] {taskinstance.py:1035} INFO - Dependencies all met for <TaskInstance: covid_ingestion.ingest_to_dwh scheduled__2021-11-13T00:00:00+00:00 [queued]>
[2021-11-15 19:47:40,042] {taskinstance.py:1035} INFO - Dependencies all met for <TaskInstance: covid_ingestion.ingest_to_dwh scheduled__2021-11-13T00:00:00+00:00 [queued]>
[2021-11-15 19:47:40,042] {taskinstance.py:1241} INFO - 
--------------------------------------------------------------------------------
[2021-11-15 19:47:40,042] {taskinstance.py:1242} INFO - Starting attempt 1 of 1
[2021-11-15 19:47:40,042] {taskinstance.py:1243} INFO - 
--------------------------------------------------------------------------------
[2021-11-15 19:47:40,057] {taskinstance.py:1262} INFO - Executing <Task(PostgresOperator): ingest_to_dwh> on 2021-11-13 00:00:00+00:00
[2021-11-15 19:47:40,060] {standard_task_runner.py:52} INFO - Started process 235 to run task
[2021-11-15 19:47:40,063] {standard_task_runner.py:76} INFO - Running: ['***', 'tasks', 'run', 'covid_ingestion', 'ingest_to_dwh', 'scheduled__2021-11-13T00:00:00+00:00', '--job-id', '22', '--raw', '--subdir', 'DAGS_FOLDER/covid_ingestion.py', '--cfg-path', '/tmp/tmp2pcmv2va', '--error-file', '/tmp/tmpgdyc_aqp']
[2021-11-15 19:47:40,064] {standard_task_runner.py:77} INFO - Job 22: Subtask ingest_to_dwh
[2021-11-15 19:47:40,096] {logging_mixin.py:109} INFO - Running <TaskInstance: covid_ingestion.ingest_to_dwh scheduled__2021-11-13T00:00:00+00:00 [running]> on host e693d79b64a2
[2021-11-15 19:47:40,176] {taskinstance.py:1429} INFO - Exporting the following env vars:
AIRFLOW_CTX_DAG_OWNER=***
AIRFLOW_CTX_DAG_ID=covid_ingestion
AIRFLOW_CTX_TASK_ID=ingest_to_dwh
AIRFLOW_CTX_EXECUTION_DATE=2021-11-13T00:00:00+00:00
AIRFLOW_CTX_DAG_RUN_ID=scheduled__2021-11-13T00:00:00+00:00
[2021-11-15 19:47:40,183] {base.py:79} INFO - Using connection to: id: postgres_dwh. Host: postgres-dwh, Port: 5432, Schema: None, Login: ***, Password: ***, extra: {}
[2021-11-15 19:47:40,186] {dbapi.py:225} INFO - Running statement: INSERT INTO dim_canton (canton_name) VALUES
  ("VS");, parameters: None
[2021-11-15 19:47:40,186] {taskinstance.py:1703} ERROR - Task failed with exception
Traceback (most recent call last):
  File "/home/airflow/.local/lib/python3.7/site-packages/airflow/models/taskinstance.py", line 1332, in _run_raw_task
    self._execute_task_with_callbacks(context)
  File "/home/airflow/.local/lib/python3.7/site-packages/airflow/models/taskinstance.py", line 1458, in _execute_task_with_callbacks
    result = self._execute_task(context, self.task)
  File "/home/airflow/.local/lib/python3.7/site-packages/airflow/models/taskinstance.py", line 1514, in _execute_task
    result = execute_callable(context=context)
  File "/home/airflow/.local/lib/python3.7/site-packages/airflow/providers/postgres/operators/postgres.py", line 69, in execute
    self.hook.run(self.sql, self.autocommit, parameters=self.parameters)
  File "/home/airflow/.local/lib/python3.7/site-packages/airflow/hooks/dbapi.py", line 205, in run
    self._run_command(cur, sql_statement, parameters)
  File "/home/airflow/.local/lib/python3.7/site-packages/airflow/hooks/dbapi.py", line 229, in _run_command
    cur.execute(sql_statement)
psycopg2.errors.UndefinedColumn: column "VS" does not exist
LINE 2:   ("VS");
           ^

[2021-11-15 19:47:40,201] {taskinstance.py:1280} INFO - Marking task as FAILED. dag_id=covid_ingestion, task_id=ingest_to_dwh, execution_date=20211113T000000, start_date=20211115T194740, end_date=20211115T194740
[2021-11-15 19:47:40,212] {standard_task_runner.py:91} ERROR - Failed to execute job 22 for task ingest_to_dwh
Traceback (most recent call last):
  File "/home/airflow/.local/lib/python3.7/site-packages/airflow/task/task_runner/standard_task_runner.py", line 85, in _start_by_fork
    args.func(args, dag=self.dag)
  File "/home/airflow/.local/lib/python3.7/site-packages/airflow/cli/cli_parser.py", line 48, in command
    return func(*args, **kwargs)
  File "/home/airflow/.local/lib/python3.7/site-packages/airflow/utils/cli.py", line 92, in wrapper
    return f(*args, **kwargs)
  File "/home/airflow/.local/lib/python3.7/site-packages/airflow/cli/commands/task_command.py", line 292, in task_run
    _run_task_by_selected_method(args, dag, ti)
  File "/home/airflow/.local/lib/python3.7/site-packages/airflow/cli/commands/task_command.py", line 107, in _run_task_by_selected_method
    _run_raw_task(args, ti)
  File "/home/airflow/.local/lib/python3.7/site-packages/airflow/cli/commands/task_command.py", line 184, in _run_raw_task
    error_file=args.error_file,
  File "/home/airflow/.local/lib/python3.7/site-packages/airflow/utils/session.py", line 70, in wrapper
    return func(*args, session=session, **kwargs)
  File "/home/airflow/.local/lib/python3.7/site-packages/airflow/models/taskinstance.py", line 1332, in _run_raw_task
    self._execute_task_with_callbacks(context)
  File "/home/airflow/.local/lib/python3.7/site-packages/airflow/models/taskinstance.py", line 1458, in _execute_task_with_callbacks
    result = self._execute_task(context, self.task)
  File "/home/airflow/.local/lib/python3.7/site-packages/airflow/models/taskinstance.py", line 1514, in _execute_task
    result = execute_callable(context=context)
  File "/home/airflow/.local/lib/python3.7/site-packages/airflow/providers/postgres/operators/postgres.py", line 69, in execute
    self.hook.run(self.sql, self.autocommit, parameters=self.parameters)
  File "/home/airflow/.local/lib/python3.7/site-packages/airflow/hooks/dbapi.py", line 205, in run
    self._run_command(cur, sql_statement, parameters)
  File "/home/airflow/.local/lib/python3.7/site-packages/airflow/hooks/dbapi.py", line 229, in _run_command
    cur.execute(sql_statement)
psycopg2.errors.UndefinedColumn: column "VS" does not exist
LINE 2:   ("VS");
           ^

[2021-11-15 19:47:40,235] {local_task_job.py:154} INFO - Task exited with return code 1
[2021-11-15 19:47:40,261] {local_task_job.py:264} INFO - 0 downstream tasks scheduled from follow-on schedule check
